<?xml version='1.0'?>

<robot name="marrtino" xmlns:xacro="http://www.ros.org/wiki/xacro">

<gazebo reference="chassis">
	<material>Gazebo/Red</material>
</gazebo>
  
  <link name='chassis'>
    <pose>0 0 0.1 0 0 0</pose>

    <inertial>
      <mass value="15.0"/>
      <origin xyz="0.0 0 0" rpy=" 0 0 0"/>
      <inertia
          ixx="0.1" ixy="0" ixz="0"
          iyy="0.1" iyz="0"
          izz="0.1"
      />
    </inertial>

    <collision name='collision_chassis'>
      <origin xyz="0 0 0.05" rpy=" 0 0 0"/> 
      <geometry>
        <box size=" 0.32 0.28 0.17"/>
        
      </geometry>
    </collision>

    <visual name='chassis_visual'>
      <origin xyz="0 0 0.05" rpy=" 0 0 0"/>
      <geometry>
       <box size=" 0.32 0.28 0.17"/>
      </geometry>
      
    </visual>


    <collision name='back_caster_collision'>
      <origin xyz="-0.15 0 -0.05" rpy=" 0 0 0"/>
      <geometry>
        <sphere radius="0.05"/>
      </geometry>
    </collision>

    <visual name='back_caster_visual'>
      <origin xyz="-0.15 0 -0.05" rpy=" 0 0 0"/>
      <geometry>
        <sphere radius="0.05"/>
      </geometry>
    </visual>

  </link>
  

<link name='right_wheel'>
    
    <pose>0 0 0.1 0 0 0</pose>

    <inertial>
      <mass value="15.0"/>
      <origin xyz="0.0 0 0" rpy=" 0 0 0"/>
      <inertia
          ixx="0.1" ixy="0" ixz="0"
          iyy="0.1" iyz="0"
          izz="0.1"
      />
    </inertial>
    
	<collision name='collision_right'>
	<origin xyz ="0 0 -0.5" rpy="0 0 0"/>
	<geometry>
	<cylinder radius="0.05" length ="0.025"/>
	</geometry>
	</collision >
	
	<visual name='right_wheel_visual'>
	<origin xyz ="0 0 -0.5" rpy="0 0 0"/>
	<geometry>
	<cylinder radius ="0.05" length ="0.025"/>
	</geometry>
	</visual >
</link>

<joint type="continuous" name="right_wheel_hinge">
	<origin xyz="0 -0.19 -0.05" rpy="0 0 0"/>
	<child link="right_wheel"/>
	<parent link =" chassis"/>
	<axis xyz="0 1 0" rpy="0 0 0"/>
	<limite fort ="10000" velocity ="1000"/>
	<joint_properties damping="1.0" friction ="1.0"/>
</joint>
  
 
  
</robot>
